<?xml version="1.0"?>
<robot name="real_steel">

  <!-- ==================== MATERIALS ==================== -->
  <material name="blue">
    <color rgba="0.2 0.4 0.8 1.0"/>
  </material>
  <material name="grey">
    <color rgba="0.5 0.5 0.5 1.0"/>
  </material>
  <material name="red">
    <color rgba="0.8 0.2 0.2 1.0"/>
  </material>

  <!-- ==================== BASE/TORSO ==================== -->
  <link name="base_link">
    <visual>
      <geometry>
        <box size="0.10 0.20 0.25"/>
      </geometry>
      <material name="grey"/>
    </visual>
    <collision>
      <geometry>
        <box size="0.10 0.20 0.25"/>
      </geometry>
    </collision>
    <inertial>
      <mass value="0.5"/>
      <inertia ixx="0.001" ixy="0" ixz="0" iyy="0.001" iyz="0" izz="0.001"/>
    </inertial>
  </link>

  <!-- ==================== LEFT ARM ==================== -->

  <!-- Left Shoulder Pan (horizontal rotation around Z) -->
  <link name="l_shoulder_pan_link">
    <visual>
      <geometry>
        <sphere radius="0.025"/>
      </geometry>
      <material name="blue"/>
    </visual>
    <collision>
      <geometry>
        <sphere radius="0.025"/>
      </geometry>
    </collision>
    <inertial>
      <mass value="0.02"/>
      <inertia ixx="0.0001" ixy="0" ixz="0" iyy="0.0001" iyz="0" izz="0.0001"/>
    </inertial>
  </link>

  <joint name="l_shoulder_pan_joint" type="revolute">
    <parent link="base_link"/>
    <child link="l_shoulder_pan_link"/>
    <origin xyz="0.0 0.12 0.10" rpy="0 0 0"/>
    <axis xyz="0 0 1"/>
    <limit lower="-1.5708" upper="1.5708" effort="10" velocity="2.0"/>
  </joint>

  <!-- Left Shoulder Tilt (vertical rotation around Y) -->
  <link name="l_shoulder_tilt_link">
    <visual>
      <origin xyz="0 0 -0.075"/>
      <geometry>
        <cylinder radius="0.02" length="0.15"/>
      </geometry>
      <material name="blue"/>
    </visual>
    <collision>
      <origin xyz="0 0 -0.075"/>
      <geometry>
        <cylinder radius="0.02" length="0.15"/>
      </geometry>
    </collision>
    <inertial>
      <mass value="0.1"/>
      <inertia ixx="0.0002" ixy="0" ixz="0" iyy="0.0002" iyz="0" izz="0.0001"/>
    </inertial>
  </link>

  <joint name="l_shoulder_tilt_joint" type="revolute">
    <parent link="l_shoulder_pan_link"/>
    <child link="l_shoulder_tilt_link"/>
    <origin xyz="0 0 0" rpy="0 0 0"/>
    <axis xyz="0 1 0"/>
    <limit lower="-0.7854" upper="2.3562" effort="10" velocity="2.0"/>
  </joint>

  <!-- Left Forearm -->
  <link name="l_forearm_link">
    <visual>
      <origin xyz="0 0 -0.06"/>
      <geometry>
        <cylinder radius="0.0175" length="0.12"/>
      </geometry>
      <material name="blue"/>
    </visual>
    <collision>
      <origin xyz="0 0 -0.06"/>
      <geometry>
        <cylinder radius="0.0175" length="0.12"/>
      </geometry>
    </collision>
    <inertial>
      <mass value="0.08"/>
      <inertia ixx="0.0001" ixy="0" ixz="0" iyy="0.0001" iyz="0" izz="0.00005"/>
    </inertial>
  </link>

  <joint name="l_elbow_joint" type="revolute">
    <parent link="l_shoulder_tilt_link"/>
    <child link="l_forearm_link"/>
    <origin xyz="0 0 -0.15" rpy="0 0 0"/>
    <axis xyz="0 1 0"/>
    <limit lower="0" upper="2.3562" effort="10" velocity="2.0"/>
  </joint>

  <!-- Left Hand -->
  <link name="l_hand_link">
    <visual>
      <geometry>
        <sphere radius="0.025"/>
      </geometry>
      <material name="red"/>
    </visual>
    <collision>
      <geometry>
        <sphere radius="0.025"/>
      </geometry>
    </collision>
    <inertial>
      <mass value="0.05"/>
      <inertia ixx="0.00002" ixy="0" ixz="0" iyy="0.00002" iyz="0" izz="0.00002"/>
    </inertial>
  </link>

  <joint name="l_hand_joint" type="fixed">
    <parent link="l_forearm_link"/>
    <child link="l_hand_link"/>
    <origin xyz="0 0 -0.12" rpy="0 0 0"/>
  </joint>

  <!-- ==================== RIGHT ARM ==================== -->

  <!-- Right Shoulder Pan (horizontal rotation around Z) -->
  <link name="r_shoulder_pan_link">
    <visual>
      <geometry>
        <sphere radius="0.025"/>
      </geometry>
      <material name="blue"/>
    </visual>
    <collision>
      <geometry>
        <sphere radius="0.025"/>
      </geometry>
    </collision>
    <inertial>
      <mass value="0.02"/>
      <inertia ixx="0.0001" ixy="0" ixz="0" iyy="0.0001" iyz="0" izz="0.0001"/>
    </inertial>
  </link>

  <joint name="r_shoulder_pan_joint" type="revolute">
    <parent link="base_link"/>
    <child link="r_shoulder_pan_link"/>
    <origin xyz="0.0 -0.12 0.10" rpy="0 0 0"/>
    <axis xyz="0 0 1"/>
    <limit lower="-1.5708" upper="1.5708" effort="10" velocity="2.0"/>
  </joint>

  <!-- Right Shoulder Tilt (vertical rotation around Y) -->
  <link name="r_shoulder_tilt_link">
    <visual>
      <origin xyz="0 0 -0.075"/>
      <geometry>
        <cylinder radius="0.02" length="0.15"/>
      </geometry>
      <material name="blue"/>
    </visual>
    <collision>
      <origin xyz="0 0 -0.075"/>
      <geometry>
        <cylinder radius="0.02" length="0.15"/>
      </geometry>
    </collision>
    <inertial>
      <mass value="0.1"/>
      <inertia ixx="0.0002" ixy="0" ixz="0" iyy="0.0002" iyz="0" izz="0.0001"/>
    </inertial>
  </link>

  <joint name="r_shoulder_tilt_joint" type="revolute">
    <parent link="r_shoulder_pan_link"/>
    <child link="r_shoulder_tilt_link"/>
    <origin xyz="0 0 0" rpy="0 0 0"/>
    <axis xyz="0 1 0"/>
    <limit lower="-0.7854" upper="2.3562" effort="10" velocity="2.0"/>
  </joint>

  <!-- Right Forearm -->
  <link name="r_forearm_link">
    <visual>
      <origin xyz="0 0 -0.06"/>
      <geometry>
        <cylinder radius="0.0175" length="0.12"/>
      </geometry>
      <material name="blue"/>
    </visual>
    <collision>
      <origin xyz="0 0 -0.06"/>
      <geometry>
        <cylinder radius="0.0175" length="0.12"/>
      </geometry>
    </collision>
    <inertial>
      <mass value="0.08"/>
      <inertia ixx="0.0001" ixy="0" ixz="0" iyy="0.0001" iyz="0" izz="0.00005"/>
    </inertial>
  </link>

  <joint name="r_elbow_joint" type="revolute">
    <parent link="r_shoulder_tilt_link"/>
    <child link="r_forearm_link"/>
    <origin xyz="0 0 -0.15" rpy="0 0 0"/>
    <axis xyz="0 1 0"/>
    <limit lower="0" upper="2.3562" effort="10" velocity="2.0"/>
  </joint>

  <!-- Right Hand -->
  <link name="r_hand_link">
    <visual>
      <geometry>
        <sphere radius="0.025"/>
      </geometry>
      <material name="red"/>
    </visual>
    <collision>
      <geometry>
        <sphere radius="0.025"/>
      </geometry>
    </collision>
    <inertial>
      <mass value="0.05"/>
      <inertia ixx="0.00002" ixy="0" ixz="0" iyy="0.00002" iyz="0" izz="0.00002"/>
    </inertial>
  </link>

  <joint name="r_hand_joint" type="fixed">
    <parent link="r_forearm_link"/>
    <child link="r_hand_link"/>
    <origin xyz="0 0 -0.12" rpy="0 0 0"/>
  </joint>

</robot>
